Traceback (most recent call last):
  File "/gpfs/projects/ailab/tnguye11/tri/cs_ope/cs_ope/experiments/experiment_learning.py", line 380, in <module>
    main(sys.argv[1:])
  File "/gpfs/projects/ailab/tnguye11/tri/cs_ope/cs_ope/experiments/experiment_learning.py", line 273, in main
    pi_behavior, pi_evaluation  = behavior_and_evaluation_policy(X, Y, train_test_split, classes, alpha=alpha)
                                  ^^^^^^^^^^^^^^^^^^^^^^^^^^^^^^^^^^^^^^^^^^^^^^^^^^^^^^^^^^^^^^^^^^^^^^^^^^^^
  File "/gpfs/projects/ailab/tnguye11/tri/cs_ope/cs_ope/experiments/experiment_learning.py", line 198, in behavior_and_evaluation_policy
    classifier = LogisticRegression(random_state=0, penalty='l2', C=0.1, solver='saga', multi_class='multinomial',).fit(X_train, Y_train)
                 ^^^^^^^^^^^^^^^^^^^^^^^^^^^^^^^^^^^^^^^^^^^^^^^^^^^^^^^^^^^^^^^^^^^^^^^^^^^^^^^^^^^^^^^^^^^^^^^^^^^^^^^^^^^^^^^^^^^^^^^^
  File "/home/tnguye11/anaconda3/envs/cs_ope/lib/python3.12/site-packages/sklearn/base.py", line 1473, in wrapper
    return fit_method(estimator, *args, **kwargs)
           ^^^^^^^^^^^^^^^^^^^^^^^^^^^^^^^^^^^^^^
  File "/home/tnguye11/anaconda3/envs/cs_ope/lib/python3.12/site-packages/sklearn/linear_model/_logistic.py", line 1223, in fit
    X, y = self._validate_data(
           ^^^^^^^^^^^^^^^^^^^^
  File "/home/tnguye11/anaconda3/envs/cs_ope/lib/python3.12/site-packages/sklearn/base.py", line 650, in _validate_data
    X, y = check_X_y(X, y, **check_params)
           ^^^^^^^^^^^^^^^^^^^^^^^^^^^^^^^
  File "/home/tnguye11/anaconda3/envs/cs_ope/lib/python3.12/site-packages/sklearn/utils/validation.py", line 1318, in check_X_y
    y = _check_y(y, multi_output=multi_output, y_numeric=y_numeric, estimator=estimator)
        ^^^^^^^^^^^^^^^^^^^^^^^^^^^^^^^^^^^^^^^^^^^^^^^^^^^^^^^^^^^^^^^^^^^^^^^^^^^^^^^^
  File "/home/tnguye11/anaconda3/envs/cs_ope/lib/python3.12/site-packages/sklearn/utils/validation.py", line 1339, in _check_y
    y = column_or_1d(y, warn=True)
        ^^^^^^^^^^^^^^^^^^^^^^^^^^
  File "/home/tnguye11/anaconda3/envs/cs_ope/lib/python3.12/site-packages/sklearn/utils/validation.py", line 1406, in column_or_1d
    raise ValueError(
ValueError: y should be a 1d array, got an array of shape (319, 2) instead.
